Workbook
Name Slicer_city: #N/A
Name Slicer_city2: #N/A
Name Slicer_pollutant_id: #N/A
Name Slicer_pollutant_id1: #N/A
Name Slicer_state: #N/A

Sheet Sheet10
A3: Row Labels | B3: Average of pollutant_avg
A4: CO | B4: 38.118993
A5: NH3 | B5: 6.0773196
A6: NO2 | B6: 33.718605
A7: OZONE | B7: 48.439535
A8: PM10 | B8: 103.56604
A9: PM2.5 | B9: 86.803241
A10: SO2 | B10: 18.2
A11: (blank)
A12: Grand Total | B12: 48.480379

Sheet chart
A3: Row Labels | B3: Average of pollutant_max
A4: Andaman and Nicobar | B4: 34.714286
A5: Andhra_Pradesh | B5: 49.578313
A6: Assam | B6: 74.653846
A7: Bihar | B7: 89.015707
A8: Chandigarh | B8: 98.8125
A9: Chhattisgarh | B9: 79.902439
A10: Delhi | B10: 172.40417
A11: Gujarat | B11: 103.86735
A12: Haryana | B12: 100.58333
A13: Himachal Pradesh | B13: 133.42857
A14: Jammu_and_Kashmir | B14: 34.333333
A15: Jharkhand | B15: 161.6
... A19: Maharashtra | B19: 81.180583
A20: Manipur
A21: Meghalaya | B21: 87.222222
A22: Mizoram | B22: 28.166667
A23: Nagaland | B23: 83.857143
A24: Odisha | B24: 82.383178
A25: Puducherry | B25: 43.571429
A26: Punjab | B26: 83.958333
A27: Rajasthan | B27: 111.49521
A28: Sikkim | B28: 85.5
A29: TamilNadu | B29: 34.873096
A30: Telangana | B30: 51.028169
A31: Tripura | B31: 53.857143
A32: Uttar_Pradesh | B32: 109.23547
... A34: West_Bengal | B34: 67.710145
A35: (blank)
A36: Grand Total | B36: 89.052097

Sheet Sheet1
A1: country | B1: state | C1: city | D1: station | E1: last_update | F1: latitude | G1: longitude | H1: pollutant_id | I1: pollutant_min | J1: pollutant_max | K1: pollutant_avg
A2: India | B2: Assam | C2: Nagaon | D2: Christianpatty, Nagaon - PCBA | E2: 45812.958 | F2: 26.349082 | G2: 92.68449 | H2: OZONE | I2: 22 | J2: 33 | K2: 26
A3: India | B3: Assam | C3: Nalbari | D3: Bata Chowk, Nalbari - PCBA | E3: 45812.958 | F3: 26.446912 | G3: 91.439057 | H3: PM10 | I3: 95 | J3: 431 | K3: 141
A4: India | B4: Assam | C4: Nalbari | D4: Bata Chowk, Nalbari - PCBA | E4: 45812.958 | F4: 26.446912 | G4: 91.439057 | H4: NO2 | I4: 1 | J4: 7 | K4: 3
A5: India | B5: Assam | C5: Nalbari | D5: Bata Chowk, Nalbari - PCBA | E5: 45812.958 | F5: 26.446912 | G5: 91.439057 | H5: NH3 | I5: 1 | J5: 1 | K5: 1
A6: India | B6: Assam | C6: Silchar | D6: Tarapur, Silchar - PCBA | E6: 45812.958 | F6: 24.82827 | G6: 92.79525 | H6: PM10 | I6: 34 | J6: 81 | K6: 53 | M6: =COUNTA(C:C) -> 3172
A7: India | B7: Assam | C7: Silchar | D7: Tarapur, Silchar - PCBA | E7: 45812.958 | F7: 24.82827 | G7: 92.79525 | H7: SO2
A8: India | B8: Assam | C8: Sivasagar | D8: Girls College, Sivasagar - PCBA | E8: 45812.958 | F8: 26.987634 | G8: 94.636574 | H8: PM2.5 | I8: 36 | J8: 82 | K8: 49
A9: India | B9: Assam | C9: Sivasagar | D9: Girls College, Sivasagar - PCBA | E9: 45812.958 | F9: 26.987634 | G9: 94.636574 | H9: CO | I9: 15 | J9: 46 | K9: 26 | M9: =AVERAGE(K:K) -> 48.480379
A10: India | B10: Bihar | C10: Araria | D10: Kharahiya Basti, Araria - BSPCB | E10: 45812.958 | F10: 26.146529 | G10: 87.454184 | H10: PM2.5 | I10: 50 | J10: 95 | K10: 78
A11: India | B11: Bihar | C11: Arrah | D11: New DM Office, Arrah - BSPCB | E11: 45812.958 | F11: 25.56261 | G11: 84.663264 | H11: NO2
A12: India | B12: Bihar | C12: Aurangabad | D12: Gurdeo Nagar, Aurangabad - BSPCB | E12: 45812.958 | F12: 24.75746 | G12: 84.366208 | H12: PM2.5 | I12: 25 | J12: 407 | K12: 190
A13: India | B13: Bihar | C13: Aurangabad | D13: Gurdeo Nagar, Aurangabad - BSPCB | E13: 45812.958 | F13: 24.75746 | G13: 84.366208 | H13: NH3 | I13: 1 | J13: 1 | K13: 1
A14: India | B14: Andhra_Pradesh | C14: Vijayawada | D14: Rajiv Nagar, Vijayawada - APPCB | E14: 45812.958 | F14: 16.554731 | G14: 80.64911 | H14: NO2 | I14: 23 | J14: 26 | K14: 25
A15: India | B15: Andhra_Pradesh | C15: Vijayawada | D15: Rajiv Nagar, Vijayawada - APPCB | E15: 45812.958 | F15: 16.554731 | G15: 80.64911 | H15: OZONE | I15: 33 | J15: 72 | K15: 38
A16: India | B16: Andhra_Pradesh | C16: Visakhapatnam | D16: GVM Corporation, Visakhapatnam - APPCB | E16: 45812.958 | F16: 17.72 | G16: 83.3 | H16: PM10 | I16: 31 | J16: 114 | K16: 75
A17: India | B17: Assam | C17: Byrnihat | D17: Central Academy for SFS, Byrnihat - PCBA | E17: 45812.958 | F17: 26.071318 | G17: 91.87488 | H17: SO2
A18: India | B18: Andhra_Pradesh | C18: Tirumala | D18: Toll Gate, Tirumala - APPCB (Formerly known as Tirumala, Tirupati - APPCB) | E18: 45812.958 | F18: 13.67 | G18: 79.35 | H18: PM2.5 | I18: 33 | J18: 82 | K18: 51
A19: India | B19: Andhra_Pradesh | C19: Tirupati | D19: Vaikuntapuram, Tirupati - APPCB | E19: 45812.958 | F19: 13.615387 | G19: 79.40923 | H19: CO | I19: 15 | J19: 26 | K19: 22
A20: India | B20: Andhra_Pradesh | C20: Vijayawada | D20: Kanuru, Vijayawada - APPCB | E20: 45812.958 | F20: 16.486692 | G20: 80.699436 | H20: NO2 | I20: 26 | J20: 127 | K20: 58
A21: India | B21: Andhra_Pradesh | C21: Anantapur | D21: Gulzarpet, Anantapur - APPCB | E21: 45812.958 | F21: 14.675886 | G21: 77.593027 | H21: PM2.5
A22: India | B22: Andhra_Pradesh | C22: Anantapur | D22: Gulzarpet, Anantapur - APPCB | E22: 45812.958 | F22: 14.675886 | G22: 77.593027 | H22: PM10 | I22: 69 | J22: 98 | K22: 78
A23: India | B23: Andhra_Pradesh | C23: Anantapur | D23: Gulzarpet, Anantapur - APPCB | E23: 45812.958 | F23: 14.675886 | G23: 77.593027 | H23: OZONE | I23: 4 | J23: 47 | K23: 34
A24: India | B24: Andhra_Pradesh | C24: Chittoor | D24: Gangineni Cheruvu, Chittoor - APPCB | E24: 45812.958 | F24: 13.20488 | G24: 79.097889 | H24: NO2 | I24: 2 | J24: 16 | K24: 9
A25: India | B25: Bihar | C25: Bettiah | D25: Kamalnath Nagar, Bettiah - BSPCB | E25: 45812.958 | F25: 26.80365 | G25: 84.51954 | H25: PM2.5 | I25: 25 | J25: 247 | K25: 109
A26: India | B26: Bihar | C26: Bettiah | D26: Kamalnath Nagar, Bettiah - BSPCB | E26: 45812.958 | F26: 26.80365 | G26: 84.51954 | H26: NO2 | I26: 28 | J26: 29 | K26: 28
A27: India | B27: Bihar | C27: Bettiah | D27: Kamalnath Nagar, Bettiah - BSPCB | E27: 45812.958 | F27: 26.80365 | G27: 84.51954 | H27: SO2 | I27: 12 | J27: 18 | K27: 15
A28: India | B28: Bihar | C28: Bhagalpur | D28: Mayaganj, Bhagalpur - BSPCB | E28: 45812.958 | F28: 25.265194 | G28: 87.012947 | H28: PM2.5 | I28: 23 | J28: 183 | K28: 88
A29: India | B29: Assam | C29: Guwahati | D29: IITG, Guwahati - PCBA | E29: 45812.958 | F29: 26.202864 | G29: 91.700464 | H29: NH3 | I29: 5 | J29: 5 | K29: 5
A30: India | B30: Assam | C30: Guwahati | D30: LGBI Airport, Guwahati - PCBA | E30: 45812.958 | F30: 26.10887 | G30: 91.589544 | H30: SO2 | I30: 1 | J30: 16 | K30: 12
A31: India | B31: Assam | C31: Guwahati | D31: Pan Bazaar, Guwahati - PCBA | E31: 45812.958 | F31: 26.1875 | G31: 91.744194 | H31: PM10 | I31: 47 | J31: 105 | K31: 84
A32: India | B32: Andaman and Nicobar | C32: Sri Vijaya Puram | D32: Police Line, Sri Vijaya Puram - ANPCC | E32: 45812.958 | F32: 11.654054 | G32: 92.734055 | H32: PM10 | I32: 6 | J32: 45 | K32: 20
A33: India | B33: Andaman and Nicobar | C33: Sri Vijaya Puram | D33: Police Line, Sri Vijaya Puram - ANPCC | E33: 45812.958 | F33: 11.654054 | G33: 92.734055 | H33: NH3 | I33: 1 | J33: 3 | K33: 1
... A44: India | B44: Bihar | C44: Saharsa | D44: Police Line, Saharsa - BSPCB | E44: 45812.958 | F44: 25.892357 | G44: 86.590325 | H44: OZONE | I44: 5 | J44: 41 | K44: 12
A45: India | B45: Bihar | C45: Kishanganj | D45: SDM Office_Khagra, Kishanganj - BSPCB | E45: 45812.958 | F45: 26.08813 | G45: 87.938403 | H45: SO2
A46: India | B46: Bihar | C46: Kishanganj | D46: SDM Office_Khagra, Kishanganj - BSPCB | E46: 45812.958 | F46: 26.08813 | G46: 87.938403 | H46: OZONE
A47: India | B47: Bihar | C47: Manguraha | D47: Forest Rest House, Manguraha - BSPCB | E47: 45812.958 | F47: 27.308328 | G47: 84.531742 | H47: SO2 | I47: 6 | J47: 7 | K47: 7
A48: India | B48: Bihar | C48: Manguraha | D48: Forest Rest House, Manguraha - BSPCB | E48: 45812.958 | F48: 27.308328 | G48: 84.531742 | H48: OZONE | I48: 12 | J48: 33 | K48: 23
A49: India | B49: Bihar | C49: Munger | D49: Town Hall, Munger - BSPCB | E49: 45812.958 | F49: 25.376776 | G49: 86.471523 | H49: PM2.5 | I49: 83 | J49: 233 | K49: 128
A50: India | B50: Bihar | C50: Munger | D50: Town Hall, Munger - BSPCB | E50: 45812.958 | F50: 25.376776 | G50: 86.471523 | H50: CO | I50: 16 | J50: 64 | K50: 33
...

Sheet state_summary
A1: state | B1: average_pollution
A2: Assam | B2: =AVERAGEIF(Sheet1!B:B, A2, Sheet1!J:J) -> 74.653846
A3: Assam | B3: =AVERAGEIF(Sheet1!B:B, A3, Sheet1!J:J) -> 74.653846
A4: Assam | B4: =AVERAGEIF(Sheet1!B:B, A4, Sheet1!J:J) -> 74.653846
A5: Assam | B5: =AVERAGEIF(Sheet1!B:B, A5, Sheet1!J:J) -> 74.653846
A6: Assam | B6: =AVERAGEIF(Sheet1!B:B, A6, Sheet1!J:J) -> 74.653846
A7: Assam | B7: =AVERAGEIF(Sheet1!B:B, A7, Sheet1!J:J) -> 74.653846
A8: Assam | B8: =AVERAGEIF(Sheet1!B:B, A8, Sheet1!J:J) -> 74.653846
A9: Assam | B9: =AVERAGEIF(Sheet1!B:B, A9, Sheet1!J:J) -> 74.653846
A10: Bihar | B10: =AVERAGEIF(Sheet1!B:B, A10, Sheet1!J:J) -> 89.015707
A11: Bihar | B11: =AVERAGEIF(Sheet1!B:B, A11, Sheet1!J:J) -> 89.015707
A12: Bihar | B12: =AVERAGEIF(Sheet1!B:B, A12, Sheet1!J:J) -> 89.015707
A13: Bihar | B13: =AVERAGEIF(Sheet1!B:B, A13, Sheet1!J:J) -> 89.015707
... A3172: West_Bengal | B3172: =AVERAGEIF(Sheet1!B:B, A3172, Sheet1!J:J) -> 67.710145

Sheet Sheet3

Sheet Sheet6
A1: last_update | B1: (All)
A3: Row Labels | B3: Average of pollutant_avg
A4: CO | B4: 38.118993
A5: NH3 | B5: 6.0773196
A6: NO2 | B6: 33.718605
A7: OZONE | B7: 48.439535
A8: PM10 | B8: 103.56604
A9: PM2.5 | B9: 86.803241
A10: SO2 | B10: 18.2
A11: Grand Total | B11: 48.480379

Sheet Sheet12

Sheet Dashboard
A1: REAL TIME AIR QUALITY INDEX
Y9: =Sheet1!M6 -> 3172
Z24: b
M30: `
